Workbook

Sheet Dashboard
A1: Herbal Monograph Control Center
A2: Use this sheet to monitor monograph completeness, citation health, total scoring, and editorial review priority before publishing. | B2: Use this sheet to monitor monograph completeness, citation health, total scoring, and editorial review priority before publishing. | C2: Use this sheet to monitor monograph completeness, citation health, total scoring, and editorial review priority before publishing. | D2: Use this sheet to monitor monograph completeness, citation health, total scoring, and editorial review priority before publishing. | E2: Use this sheet to monitor monograph completeness, citation health, total scoring, and editorial review priority before publishing. | F2: Use this sheet to monitor monograph completeness, citation health, total scoring, and editorial review priority before publishing. | G2: Use this sheet to monitor monograph completeness, citation health, total scoring, and editorial review priority before publishing. | H2: Use this sheet to monitor monograph completeness, citation health, total scoring, and editorial review priority before publishing. | J2: Next Upgrade Panel
A3: KPI | B3: Value | D3: Score band | E3: Count | G3: Citation health | H3: Count | J3: Mechanism tags tracked | K3: 13
A4: Total monographs | B4: 17 | D4: 8+ | E4: 6 | G4: Present | H4: 11 | J4: Rows needing source normalization | K4: 6
A5: Schema-upgraded rows | B5: 17 | D5: 7 | E5: 4 | G5: Needs normalization | H5: 6 | J5: Rows with missing dosage | K5: 0
A6: High-confidence rows | B6: 4 | D6: 6 | E6: 7 | G6: Partial/missing | H6: 0 | J6: Rows marked Ready | K6: 0
A7: Citation present | B7: 11 | D7: <=5 | E7: 0
A8: Needs normalization | B8: 6
A9: Average total score | B9: 6.9
A10: Immediate actions | B10: Count | D10: Publishing readiness | E10: Count | G10: Review priority | H10: Count
A11: Missing dosage | B11: 10 | D11: Ready | E11: 6 | G11: High | H11: 6
A12: Missing standardization | B12: 8 | D12: Near ready | E12: 11 | G12: Medium | H12: 11
A13: Missing marker compounds | B13: 5 | D13: Needs work | E13: 0 | G13: Low | H13: 0
A14: Low or medium confidence | B14: 13
A16: Monograph workflow rules
A17: High review priority | B17: Citation normalization missing or citation status is missing.
A18: Medium review priority | B18: Core monograph fields missing such as dosage, standardization, or marker compounds.
A19: Ready | B19: High field coverage with present citations; suitable for editorial polishing and publication prep.

Sheet Herb Monographs
A1: name | B1: slug | C1: scientificName | D1: monographType | E1: category | F1: plantPartUsed | G1: commonNames | H1: region | I1: summary | J1: description | K1: activeCompounds | L1: markerCompounds | M1: mechanism | N1: mechanismTags | O1: evidenceLevel | P1: safetyNotes | Q1: interactions | R1: contraindications | S1: preparation | T1: dosage | U1: standardization | V1: qualityConcerns | W1: confidence | X1: status | Y1: sources | Z1: citationStatus | AA1: sourceAuthority | AB1: summaryCitations | AC1: mechanismCitations | AD1: safetyCitations | AE1: interactionCitations | AF1: notesForCodex | AG1: score_confidence | AH1: score_evidence | AI1: score_citation | AJ1: totalScore | AK1: reviewPriority | AL1: dosageStatus | AM1: sourceTier | AN1: completenessPct | AO1: readinessFlag | AP1: editorialOwner | AQ1: reviewDate | AR1: publishStatus | AS1: qaStatus | AT1: sourceLockFlag | AU1: frontendReadyFlag | AV1: webCopyReadyFlag | AW1: publishBlocker | AX1: reviewRound | AY1: reviewerName | AZ1: reviewerRole | BA1: reviewStage | BB1: reviewStatus | BC1: reviewerNotes | BD1: approvalTimestamp | BE1: lastModifiedTimestamp | BF1: changeSummary | BG1: rowReviewKey | BH1: historyEntries
A2: Ashwagandha | B2: ashwagandha | C2: Withania somnifera | D2: herb | E2: shrub | F2: root | G2: ashwagandha; Indian ginseng; winter cherry | H2: Native to India, the Middle East and parts of Africa and Asia. | I2: Ashwagandha (Withania somnifera) is a shrub monograph focused on the root used in herbal preparations. It is associated with Native to India, the Middle East and parts of Africa and Asia. Withanolides are thought to mediate adaptogenic and neuroprotective effects by modulating HPA-axis signaling, NF-κB, Nrf2 and GABAergic pathways. Short-term use appears safe; side effects include drowsiness and GI upset. | J2: Ashwagandha is represented here as a monograph-style entry centered on the root. Key reported compounds include withaferin A; withanolide D; withanolide A; withanoside IV; sitoindosides; alkaloids. Typical preparation forms: Root powders and standardized extracts. Withanolides are thought to mediate adaptogenic and neuroprotective effects by modulating HPA-axis signaling, NF-κB, Nrf2 and GABAergic pathways. Interaction profile: May potentiate sedatives, antihypertensives, antidiabetics, thyroid hormones, and immunosuppressants. Use caution or avoid in: Pregnancy, breastfeeding, autoimmune disease, thyroid disorders, liver disease. | K2: withaferin A; withanolide D; withanolide A; withanoside IV; sitoindosides; alkaloids | L2: withanolides | M2: Withanolides are thought to mediate adaptogenic and neuroprotective effects by modulating HPA-axis signaling, NF-κB, Nrf2 and GABAergic pathways. | N2: adaptogen; anti-inflammatory; antioxidant; gabaergic | O2: human + preclinical | P2: Short-term use appears safe; side effects include drowsiness and GI upset. Rare liver injury has been reported. | Q2: May potentiate sedatives, antihypertensives, antidiabetics, thyroid hormones, and immunosuppressants. | R2: Pregnancy, breastfeeding, autoimmune disease, thyroid disorders, liver disease. | S2: Root powders and standardized extracts. | T2: 300–500 mg root extract twice daily | U2: Often standardized to withanolides. | W2: medium | X2: schema-upgraded | Y2: Recovered from prior batch output in this conversation | Z2: needs-source-normalization | AA2: conversation-recovered | AB2: Recovered from prior batch output in this conversation | AC2: Recovered from prior batch output in this conversation | AD2: Recovered from prior batch output in this conversation | AE2: Recovered from prior batch output in this conversation | AF2: Separate root-based products from leaf-heavy extracts. | AG2: 2 | AH2: 3 | AI2: 1 | AJ2: 6 | AK2: High | AL2: Present | AM2: Conversation-recovered | AN2: 1 | AO2: Near ready | AP2: Research | AR2: Source review | AS2: Not started | AT2: No | AU2: No | AV2: Yes | AW2: Normalize source record | AX2: 1 | BA2: =IF($AR2="Published","Published",IF($AS2="Passed","Approved",IF($AR2="Ready for QA","QA review",IF($AR2="Source review","Source review",IF($AR2="Editorial polish","Editorial review","Review pending"))))) | BB2: =IF(OR($AR2="Published",$AS2="Passed",AND($AY2<>"",$BD2<>"")),"Approved",IF(OR($AY2<>"",$BC2<>"",$BF2<>""),"In review","Pending")) | BE2: =IF(OR($AY2<>"",$AZ2<>"",$BC2<>"",$BF2<>""),TODAY(),"") | BG2: =$B2&"-R"&$AX2 | BH2: =COUNTIF('Change History'!$C:$C,$B2)
A3: Black Cohosh | B3: black-cohosh | C3: Actaea racemosa | D3: herb | E3: rhizome | F3: root; rhizome | G3: black cohosh; black snakeroot; Actaea racemosa | H3: Native to North America, especially the eastern United States. | I3: Black Cohosh (Actaea racemosa) is a rhizome monograph focused on the root; rhizome used in herbal preparations. It is associated with Native to North America, especially the eastern United States. Proposed mechanism based on preclinical and limited clinical data: black cohosh may act through serotonergic pathways, selective estrogen receptor modulation, and anti-inflammatory signaling rather than as a classical estrogen. Generally well tolerated in short-term studies, but rare cases of liver injury have been reported. | J3: Black Cohosh is represented here as a monograph-style entry centered on the root; rhizome. Key reported compounds include triterpene glycosides (actein, 23-epi-26-deoxyactein); cimifugoside; caffeic acid derivatives; fukinolic acid. Typical preparation forms: Root and rhizome used in standardized extracts, capsules, tablets, and tinctures. Proposed mechanism based on preclinical and limited clinical data: black cohosh may act through serotonergic pathways, selective estrogen receptor modulation, and anti-inflammatory signaling rather than as a classical estrogen. Interaction profile: Potential interactions with hepatotoxic drugs and with medications affecting estrogen or serotonergic pathways. Use caution or avoid in: Avoid in pregnancy and breastfeeding. Use caution in liver disease or hormone-sensitive conditions. | K3: triterpene glycosides (actein, 23-epi-26-deoxyactein); cimifugoside; caffeic acid derivatives; fukinolic acid | L3: actein; 23-epi-26-deoxyactein | M3: Proposed mechanism based on preclinical and limited clinical data: black cohosh may act through serotonergic pathways, selective estrogen receptor modulation, and anti-inflammatory signaling rather than as a classical estrogen. | N3: serotonergic; anti-inflammatory; hormonal | O3: preclinical + limited human | P3: Generally well tolerated in short-term studies, but rare cases of liver injury have been reported. Product contamination or misidentification is a known issue. | Q3: Potential interactions with hepatotoxic drugs and with medications affecting estrogen or serotonergic pathways. | R3: Avoid in pregnancy and breastfeeding. Use caution in liver disease or hormone-sensitive conditions. | S3: Root and rhizome used in standardized extracts, capsules, tablets, and tinctures. | V3: Adulteration/misidentification risk in commercial products. | W3: medium | X3: schema-upgraded | Y3: NCCIH; NIH ODS; PubMed mechanism review PMC3046019 | Z3: present | AA3: NCCIH; NIH/ODS; PubMed/PMC | AB3: NCCIH; NIH ODS; PubMed mechanism review PMC3046019 | AC3: NCCIH; NIH ODS; PubMed mechanism review PMC3046019 | AD3: NCCIH; NIH ODS; PubMed mechanism review PMC3046019 | AE3: NCCIH; NIH ODS; PubMed mechanism review PMC3046019 | AF3: Treat menopausal mechanism claims as mixed evidence, not established estrogenic action. | AG3: 2 | AH3: 3 | AI3: 3 | AJ3: 8 | AK3: Medium | AL3: Missing | AM3: Linked primary/secondary | AN3: 0.85714286 | AO3: Ready | AP3: Editorial | AR3: Ready for QA | AS3: Not started | AT3: Yes | AU3: Yes | AV3: Yes | AX3: 1 | BA3: =IF($AR3="Published","Published",IF($AS3="Passed","Approved",IF($AR3="Ready for QA","QA review",IF($AR3="Source review","Source review",IF($AR3="Editorial polish","Editorial review","Review pending"))))) | BB3: =IF(OR($AR3="Published",$AS3="Passed",AND($AY3<>"",$BD3<>"")),"Approved",IF(OR($AY3<>"",$BC3<>"",$BF3<>""),"In review","Pending")) | BE3: =IF(OR($AY3<>"",$AZ3<>"",$BC3<>"",$BF3<>""),TODAY(),"") | BG3: =$B3&"-R"&$AX3 | BH3: =COUNTIF('Change History'!$C:$C,$B3)
A4: Echinacea Purpurea | B4: echinacea-purpurea | C4: Echinacea purpurea | D4: herb | E4: herb | F4: unspecified | G4: echinacea; purple coneflower | H4: Native to the central and eastern United States; now cultivated and introduced in Europe and other temperate regions【55003496660111†L75-L130】. | I4: Echinacea Purpurea (Echinacea purpurea) is a herb monograph focused on the unspecified used in herbal preparations. It is associated with Native to the central and eastern United States; now cultivated and introduced in Europe and other temperate regions【55003496660111†L75-L130】. Roots, leaves and flowers of Echinacea purpurea contain mixtures of lipophilic alkamides and hydrophilic caffeic acid derivatives such as chicoric acid and echinacoside, along with polysaccharides and glycoproteins【880087072039746†L166-L200】【840476591578855†L240-L305】. Short‑term use of echinacea extracts appears safe for most adults. | J4: Echinacea Purpurea is represented here as a monograph-style entry centered on the unspecified. Key reported compounds include alkamides; chicoric acid; echinacoside; caffeic acid; cynarin. Typical preparation forms: Medicinal products use the roots and aerial parts in teas, juices, tinctures and standardized extracts. Roots, leaves and flowers of Echinacea purpurea contain mixtures of lipophilic alkamides and hydrophilic caffeic acid derivatives such as chicoric acid and echinacoside, along with polysaccharides and glycoproteins【880087072039746†L166-L200】【840476591578855†L240-L305】. These constituents stimulate immune function by enhancing phagocytosis, activating fibroblasts and respiratory burst activity, and modulating nitric‑oxide and cytokine production via cannabinoid type‑2 receptors【880087072039746†L215-L243】. They also inhibit cyclo‑oxygenase and lipoxygenase enzymes. Most mechanistic data are from cell and animal studies; human evidence is limited. Interaction profile: Echinacea may interact with immunosuppressant drugs by stimulating immune activity and could affect the pharmacokinetics of drugs metabolised by cytochrome P450 enzymes; caution is advised when taken with hepatic substrates or caffeine. Use caution or avoid in: Individuals with autoimmune disorders or allergies to ragweed and other Asteraceae plants should avoid echinacea. Use during pregnancy or breastfeeding is not recommended. People taking immunosuppressant drugs should avoid echinacea due to potential antagonism. | K4: alkamides; chicoric acid; echinacoside; caffeic acid; cynarin | M4: Roots, leaves and flowers of Echinacea purpurea contain mixtures of lipophilic alkamides and hydrophilic caffeic acid derivatives such as chicoric acid and echinacoside, along with polysaccharides and glycoproteins【880087072039746†L166-L200】【840476591578855†L240-L305】. These constituents stimulate immune function by enhancing phagocytosis, activating fibroblasts and respiratory burst activity, and modulating nitric‑oxide and cytokine production via cannabinoid type‑2 receptors【880087072039746†L215-L243】. They also inhibit cyclo‑oxygenase and lipoxygenase enzymes. Most mechanistic data are from cell and animal studies; human evidence is limited. | N4: immunomodulatory | P4: Short‑term use of echinacea extracts appears safe for most adults. Reported side effects include digestive upset and rash; allergic reactions can occur, especially in individuals sensitive to plants in the Asteraceae family. Some children have developed rashes after echinacea use. Safety during pregnancy or breastfeeding is not established. There is conflicting evidence about whether echinacea alters the metabolism of drugs processed by the liver; theoretical interactions with immunosuppressants or caffeine have been proposed【246299874455786†L194-L213】. | Q4: Echinacea may interact with immunosuppressant drugs by stimulating immune activity and could affect the pharmacokinetics of drugs metabolised by cytochrome P450 enzymes; caution is advised when taken with hepatic substrates or caffeine. | R4: Individuals with autoimmune disorders or allergies to ragweed and other Asteraceae plants should avoid echinacea. Use during pregnancy or breastfeeding is not recommended. People taking immunosuppressant drugs should avoid echinacea due to potential antagonism. | S4: Medicinal products use the roots and aerial parts in teas, juices, tinctures and standardized extracts. | W4: medium | X4: schema-upgraded | Y4: 【880087072039746†L166-L200】; 【880087072039746†L215-L243】; 【840476591578855†L240-L305】; 【246299874455786†L194-L213】; 【55003496660111†L75-L130】 | Z4: present | AA4: PubMed/PMC | AB4: 【880087072039746†L166-L200】; 【880087072039746†L215-L243】; 【840476591578855†L240-L305】; 【246299874455786†L194-L213】; 【55003496660111†L75-L130】 | AC4: 【880087072039746†L166-L200】; 【880087072039746†L215-L243】; 【840476591578855†L240-L305】; 【246299874455786†L194-L213】; 【55003496660111†L75-L130】 | AD4: 【880087072039746†L166-L200】; 【880087072039746†L215-L243】; 【840476591578855†L240-L305】; 【246299874455786†L194-L213】; 【55003496660111†L75-L130】 | AE4: 【880087072039746†L166-L200】; 【880087072039746†L215-L243】; 【840476591578855†L240-L305】; 【246299874455786†L194-L213】; 【55003496660111†L75-L130】 | AF4: Mechanism preserved as qualified language where evidence is preclinical. | AG4: 2 | AH4: 1 | AI4: 3 | AJ4: 6 | AK4: Medium | AL4: Missing | AM4: Linked primary/secondary | AN4: 0.71428571 | AO4: Near ready | AP4: Editorial | AR4: Editorial polish | AS4: Not started | AT4: Yes | AU4: No | AV4: Yes | AW4: Finalize remaining content gaps | AX4: 1 | BA4: =IF($AR4="Published","Published",IF($AS4="Passed","Approved",IF($AR4="Ready for QA","QA review",IF($AR4="Source review","Source review",IF($AR4="Editorial polish","Editorial review","Review pending"))))) | BB4: =IF(OR($AR4="Published",$AS4="Passed",AND($AY4<>"",$BD4<>"")),"Approved",IF(OR($AY4<>"",$BC4<>"",$BF4<>""),"In review","Pending")) | BE4: =IF(OR($AY4<>"",$AZ4<>"",$BC4<>"",$BF4<>""),TODAY(),"") | BG4: =$B4&"-R"&$AX4 | BH4: =COUNTIF('Change History'!$C:$C,$B4)
A5: Garlic | B5: garlic | C5: Allium sativum | D5: herb | E5: bulb | F5: unspecified | G5: garlic; Allium sativum | H5: Native to parts of Central Asia including Iran, Kazakhstan, Kyrgyzstan, Tajikistan, Turkmenistan and Uzbekistan, but now cultivated worldwide【387438139344369†L214-L229】. | I5: Garlic (Allium sativum) is a bulb monograph focused on the unspecified used in herbal preparations. It is associated with Native to parts of Central Asia including Iran, Kazakhstan, Kyrgyzstan, Tajikistan, Turkmenistan and Uzbekistan, but now cultivated worldwide【387438139344369†L214-L229】. Garlic bulbs contain organosulfur compounds such as diallyl sulfide, diallyl disulfide, diallyl trisulfide, ajoene and S‑allyl‑cysteine. Oral garlic preparations are generally safe when used for up to seven years; side effects include breath and body odour, abdominal pain, flatulence and nausea. | J5: Garlic is represented here as a monograph-style entry centered on the unspecified. Key reported compounds include diallyl sulfide; diallyl disulfide; diallyl trisulfide; ajoene; S‑allyl‑cysteine. Typical preparation forms: Fresh or dried bulbs are used as food and in remedies. Commercial supplements include aged garlic extracts, oils and powders standardized for organosulfur content. Garlic bulbs contain organosulfur compounds such as diallyl sulfide, diallyl disulfide, diallyl trisulfide, ajoene and S‑allyl‑cysteine. These constituents exert antioxidant, anti‑inflammatory and immunomodulatory effects in vitro and in animal models by scavenging free radicals and modulating inflammatory pathways. Human evidence is limited, so this should be regarded as a proposed mechanism based on preclinical data. Interaction profile: Garlic may potentiate the effects of anticoagulant and antiplatelet drugs (e.g., warfarin, aspirin) and should be discontinued before surgery. It may also enhance the effects of antihypertensive or antidiabetic medicines. Use caution or avoid in: People with bleeding disorders, those taking anticoagulant or antiplatelet drugs and individuals scheduled for surgery should avoid high‑dose garlic supplements. Because safety during pregnancy and breastfeeding has not been established, garlic supplements are not recommended in these populations. | K5: diallyl sulfide; diallyl disulfide; diallyl trisulfide; ajoene; S‑allyl‑cysteine | M5: Garlic bulbs contain organosulfur compounds such as diallyl sulfide, diallyl disulfide, diallyl trisulfide, ajoene and S‑allyl‑cysteine. These constituents exert antioxidant, anti‑inflammatory and immunomodulatory effects in vitro and in animal models by scavenging free radicals and modulating inflammatory pathways. Human evidence is limited, so this should be regarded as a proposed mechanism based on preclinical data. | N5: anti-inflammatory; antioxidant; immunomodulatory | P5: Oral garlic preparations are generally safe when used for up to seven years; side effects include breath and body odour, abdominal pain, flatulence and nausea. Because garlic can inhibit platelet aggregation it may increase the risk of bleeding, especially when combined with anticoagulants or antiplatelet drugs. Raw garlic applied to the skin can cause severe irritation or burns. The safety of garlic supplements during pregnancy or breastfeeding is uncertain【945608786527328†L190-L207】. | Q5: Garlic may potentiate the effects of anticoagulant and antiplatelet drugs (e.g., warfarin, aspirin) and should be discontinued before surgery. It may also enhance the effects of antihypertensive or antidiabetic medicines. | R5: People with bleeding disorders, those taking anticoagulant or antiplatelet drugs and individuals scheduled for surgery should avoid high‑dose garlic supplements. Because safety during pregnancy and breastfeeding has not been established, garlic supplements are not recommended in these populations. | S5: Fresh or dried bulbs are used as food and in remedies. Commercial supplements include aged garlic extracts, oils and powders standardized for organosulfur content. | W5: medium | X5: schema-upgraded | Y5: 【170738571486764†L1208-L1216】; 【945608786527328†L190-L207】; 【387438139344369†L214-L229】 | Z5: present | AA5: PubMed/PMC | AB5: 【170738571486764†L1208-L1216】; 【945608786527328†L190-L207】; 【387438139344369†L214-L229】 | AC5: 【170738571486764†L1208-L1216】; 【945608786527328†L190-L207】; 【387438139344369†L214-L229】 | AD5: 【170738571486764†L1208-L1216】; 【945608786527328†L190-L207】; 【387438139344369†L214-L229】 | AE5: 【170738571486764†L1208-L1216】; 【945608786527328†L190-L207】; 【387438139344369†L214-L229】 | AF5: Mechanism preserved as qualified language where evidence is preclinical. | AG5: 2 | AH5: 1 | AI5: 3 | AJ5: 6 | AK5: Medium | AL5: Missing | AM5: Linked primary/secondary | AN5: 0.71428571 | AO5: Near ready | AP5: Editorial | AR5: Editorial polish | AS5: Not started | AT5: Yes | AU5: No | AV5: Yes | AW5: Finalize remaining content gaps | AX5: 1 | BA5: =IF($AR5="Published","Published",IF($AS5="Passed","Approved",IF($AR5="Ready for QA","QA review",IF($AR5="Source review","Source review",IF($AR5="Editorial polish","Editorial review","Review pending"))))) | BB5: =IF(OR($AR5="Published",$AS5="Passed",AND($AY5<>"",$BD5<>"")),"Approved",IF(OR($AY5<>"",$BC5<>"",$BF5<>""),"In review","Pending")) | BE5: =IF(OR($AY5<>"",$AZ5<>"",$BC5<>"",$BF5<>""),TODAY(),"") | BG5: =$B5&"-R"&$AX5 | BH5: =COUNTIF('Change History'!$C:$C,$B5)
A6: Ginger | B6: ginger | C6: Zingiber officinale | D6: herb | E6: rhizome | F6: unspecified | G6: ginger; Zingiber officinale | H6: Ginger does not occur in the wild; it is believed to have originated in Southeast Asia and is now cultivated across the humid tropics with India as the largest producer【418916103730052†L148-L163】. | I6: Ginger (Zingiber officinale) is a rhizome monograph focused on the unspecified used in herbal preparations. It is associated with Ginger does not occur in the wild; it is believed to have originated in Southeast Asia and is now cultivated across the humid tropics with India as the largest producer【418916103730052†L148-L163】. Ginger rhizomes contain phenolic constituents such as gingerols, shogaols, zingerone and paradols. Ginger is widely consumed as a food and supplement and is generally regarded as safe. | J6: Ginger is represented here as a monograph-style entry centered on the unspecified. Key reported compounds include [6]-gingerol; shogaols; zingerone; paradols. Typical preparation forms: The rhizome is used fresh, dried, pickled, preserved, candied or powdered. Supplements include encapsulated dried powders and extracts【418916103730052†L176-L189】. Ginger rhizomes contain phenolic constituents such as gingerols, shogaols, zingerone and paradols. These compounds modulate immune‑cell function and regulate signalling pathways including nuclear factor‑κB, MAPK and PI3K/Akt/mTOR, and they can activate AMP‑activated protein kinase (AMPK), NRF2, HO‑1 and PPARγ【69571933386645†L153-L169】【69571933386645†L240-L249】. Through these mechanisms ginger exhibits anti‑inflammatory, antioxidant and neuroprotective effects. Interaction profile: Ginger may increase the risk of bleeding when taken with anticoagulant or antiplatelet drugs and could lower blood glucose or blood pressure, potentiating antidiabetic or antihypertensive medications. Use caution or avoid in: Use cautiously in pregnancy, gallstone disease or bleeding disorders. Discontinue before surgery and avoid high‑dose supplements when taking anticoagulants. | K6: [6]-gingerol; shogaols; zingerone; paradols | M6: Ginger rhizomes contain phenolic constituents such as gingerols, shogaols, zingerone and paradols. These compounds modulate immune‑cell function and regulate signalling pathways including nuclear factor‑κB, MAPK and PI3K/Akt/mTOR, and they can activate AMP‑activated protein kinase (AMPK), NRF2, HO‑1 and PPARγ【69571933386645†L153-L169】【69571933386645†L240-L249】. Through these mechanisms ginger exhibits anti‑inflammatory, antioxidant and neuroprotective effects. | N6: anti-inflammatory; antioxidant; immunomodulatory | P6: Ginger is widely consumed as a food and supplement and is generally regarded as safe. Research suggests it may help with mild nausea and menstrual cramps. Reported side effects at high doses include abdominal discomfort, heartburn, diarrhoea and irritation of the mouth or throat【799387966105800†L29-L56】. Clinical studies using up to 1 000 mg/day of dried powdered extract report adverse event rates similar to placebo【739669106228210†L96-L133】. The safety of high‑dose ginger during pregnancy has not been conclusively established. | Q6: Ginger may increase the risk of bleeding when taken with anticoagulant or antiplatelet drugs and could lower blood glucose or blood pressure, potentiating antidiabetic or antihypertensive medications. | R6: Use cautiously in pregnancy, gallstone disease or bleeding disorders. Discontinue before surgery and avoid high‑dose supplements when taking anticoagulants. | S6: The rhizome is used fresh, dried, pickled, preserved, candied or powdered. Supplements include encapsulated dried powders and extracts【418916103730052†L176-L189】. | T6: Typical adult dose is up to 1 000 mg/day of dried powdered extract for gastrointestinal complaints【739669106228210†L96-L133】. | W6: high | X6: schema-upgraded | Y6: 【69571933386645†L153-L169】; 【69571933386645†L240-L249】; 【799387966105800†L29-L56】; 【739669106228210†L96-L133】; 【418916103730052†L148-L163】; 【418916103730052†L176-L189】 | Z6: present | AA6: PubMed/PMC | AB6: 【69571933386645†L153-L169】; 【69571933386645†L240-L249】; 【799387966105800†L29-L56】; 【739669106228210†L96-L133】; 【418916103730052†L148-L163】; 【418916103730052†L176-L189】 | AC6: 【69571933386645†L153-L169】; 【69571933386645†L240-L249】; 【799387966105800†L29-L56】; 【739669106228210†L96-L133】; 【418916103730052†L148-L163】; 【418916103730052†L176-L189】 | AD6: 【69571933386645†L153-L169】; 【69571933386645†L240-L249】; 【799387966105800†L29-L56】; 【739669106228210†L96-L133】; 【418916103730052†L148-L163】; 【418916103730052†L176-L189】 | AE6: 【69571933386645†L153-L169】; 【69571933386645†L240-L249】; 【799387966105800†L29-L56】; 【739669106228210†L96-L133】; 【418916103730052†L148-L163】; 【418916103730052†L176-L189】 | AF6: Mechanism preserved as qualified language where evidence is preclinical. | AG6: 3 | AH6: 1 | AI6: 3 | AJ6: 7 | AK6: Medium | AL6: Present | AM6: Linked primary/secondary | AN6: 0.78571429 | AO6: Near ready | AP6: Editorial | AR6: Editorial polish | AS6: Not started | AT6: Yes | AU6: No | AV6: Yes | AW6: Finalize remaining content gaps | AX6: 1 | BA6: =IF($AR6="Published","Published",IF($AS6="Passed","Approved",IF($AR6="Ready for QA","QA review",IF($AR6="Source review","Source review",IF($AR6="Editorial polish","Editorial review","Review pending"))))) | BB6: =IF(OR($AR6="Published",$AS6="Passed",AND($AY6<>"",$BD6<>"")),"Approved",IF(OR($AY6<>"",$BC6<>"",$BF6<>""),"In review","Pending")) | BE6: =IF(OR($AY6<>"",$AZ6<>"",$BC6<>"",$BF6<>""),TODAY(),"") | BG6: =$B6&"-R"&$AX6 | BH6: =COUNTIF('Change History'!$C:$C,$B6)
A7: Ginkgo Biloba | B7: ginkgo-biloba | C7: Ginkgo biloba | D7: herb | E7: tree | F7: leaf | G7: ginkgo; maidenhair tree | H7: Native to China; cultivated worldwide as an ornamental and medicinal tree. | I7: Ginkgo Biloba (Ginkgo biloba) is a tree monograph focused on the leaf used in herbal preparations. It is associated with Native to China; cultivated worldwide as an ornamental and medicinal tree. The standardized leaf extract (EGb 761) contains terpene lactones and flavone glycosides that modulate multiple neurotransmitter systems and platelet-activating factor pathways. Appears safe at recommended doses, but fresh seeds are toxic. | J7: Ginkgo Biloba is represented here as a monograph-style entry centered on the leaf. Key reported compounds include ginkgolides A, B, C, J; bilobalide; ginkgetin; bilobetin; sciadopitysin. Typical preparation forms: Standardized leaf extract (EGb 761). The standardized leaf extract (EGb 761) contains terpene lactones and flavone glycosides that modulate multiple neurotransmitter systems and platelet-activating factor pathways. Interaction profile: May potentiate NSAIDs, anticoagulants, antiplatelets, and interact with antidepressants and antidiabetic drugs. Use caution or avoid in: Pregnancy, breastfeeding, bleeding disorders, epilepsy, planned surgery. | K7: ginkgolides A, B, C, J; bilobalide; ginkgetin; bilobetin; sciadopitysin | L7: ginkgolides; bilobalide | M7: The standardized leaf extract (EGb 761) contains terpene lactones and flavone glycosides that modulate multiple neurotransmitter systems and platelet-activating factor pathways. | N7: dopaminergic; serotonergic; cholinergic; antioxidant | O7: human + preclinical | P7: Appears safe at recommended doses, but fresh seeds are toxic. May increase bleeding risk and lower seizure threshold. | Q7: May potentiate NSAIDs, anticoagulants, antiplatelets, and interact with antidepressants and antidiabetic drugs. | R7: Pregnancy, breastfeeding, bleeding disorders, epilepsy, planned surgery. | S7: Standardized leaf extract (EGb 761). | T7: 120–240 mg/day standardized extract | U7: Typically 24% flavonoid glycosides and 6% terpene lactones. | W7: high | X7: schema-upgraded | Y7: Recovered from prior batch output in this conversation | Z7: needs-source-normalization | AA7: conversation-recovered | AB7: Recovered from prior batch output in this conversation | AC7: Recovered from prior batch output in this conversation | AD7: Recovered from prior batch output in this conversation | AE7: Recovered from prior batch output in this conversation | AF7: Keep seed toxicity distinct from leaf-extract use. | AG7: 3 | AH7: 3 | AI7: 1 | AJ7: 7 | AK7: High | AL7: Present | AM7: Conversation-recovered | AN7: 1 | AO7: Near ready | AP7: Research | AR7: Source review | AS7: Not started | AT7: No | AU7: No | AV7: Yes | AW7: Normalize source record | AX7: 1 | BA7: =IF($AR7="Published","Published",IF($AS7="Passed","Approved",IF($AR7="Ready for QA","QA review",IF($AR7="Source review","Source review",IF($AR7="Editorial polish","Editorial review","Review pending"))))) | BB7: =IF(OR($AR7="Published",$AS7="Passed",AND($AY7<>"",$BD7<>"")),"Approved",IF(OR($AY7<>"",$BC7<>"",$BF7<>""),"In review","Pending")) | BE7: =IF(OR($AY7<>"",$AZ7<>"",$BC7<>"",$BF7<>""),TODAY(),"") | BG7: =$B7&"-R"&$AX7 | BH7: =COUNTIF('Change History'!$C:$C,$B7)
A8: Holy Basil | B8: holy-basil | C8: Ocimum tenuiflorum | D8: herb | E8: herb | F8: leaf; aerial parts | H8: India, Southeast Asia | I8: Holy Basil (Ocimum tenuiflorum) is a herb monograph focused on the leaf; aerial parts used in herbal preparations. It is associated with India, Southeast Asia. Adaptogenic; anti-inflammatory; modulates cortisol and stress pathways. Generally safe; possible mild GI upset. | J8: Holy Basil is represented here as a monograph-style entry centered on the leaf; aerial parts. Key reported compounds include eugenol; ursolic acid; rosmarinic acid. Typical preparation forms: Leaf extracts, teas. Adaptogenic; anti-inflammatory; modulates cortisol and stress pathways. Interaction profile: Anticoagulants, antidiabetic drugs. Use caution or avoid in: Pregnancy (limited data). | K8: eugenol; ursolic acid; rosmarinic acid | L8: eugenol; ursolic acid | M8: Adaptogenic; anti-inflammatory; modulates cortisol and stress pathways | N8: adaptogen; anti-inflammatory; antioxidant | O8: preclinical + limited human | P8: Generally safe; possible mild GI upset | Q8: Anticoagulants, antidiabetic drugs | R8: Pregnancy (limited data) | S8: Leaf extracts, teas | U8: Eugenol or ursolic acid content | W8: medium | X8: schema-upgraded | Y8: NCCIH; PubMed | Z8: present | AA8: NCCIH; PubMed/PMC | AB8: NCCIH; PubMed | AC8: NCCIH; PubMed | AD8: NCCIH; PubMed | AE8: NCCIH; PubMed | AF8: Carried forward from batch CSV; needs source-linked monograph expansion. | AG8: 2 | AH8: 3 | AI8: 3 | AJ8: 8 | AK8: Medium | AL8: Missing | AM8: Linked primary/secondary | AN8: 0.92857143 | AO8: Ready | AP8: Editorial | AR8: Ready for QA | AS8: Not started | AT8: Yes | AU8: Yes | AV8: Yes | AX8: 1 | BA8: =IF($AR8="Published","Published",IF($AS8="Passed","Approved",IF($AR8="Ready for QA","QA review",IF($AR8="Source review","Source review",IF($AR8="Editorial polish","Editorial review","Review pending"))))) | BB8: =IF(OR($AR8="Published",$AS8="Passed",AND($AY8<>"",$BD8<>"")),"Approved",IF(OR($AY8<>"",$BC8<>"",$BF8<>""),"In review","Pending")) | BE8: =IF(OR($AY8<>"",$AZ8<>"",$BC8<>"",$BF8<>""),TODAY(),"") | BG8: =$B8&"-R"&$AX8 | BH8: =COUNTIF('Change History'!$C:$C,$B8)
A9: Kava | B9: kava | C9: Piper methysticum | D9: herb | E9: shrub | F9: root; rhizome | G9: kava; kava-kava; awa; yaqona | H9: Indigenous to the South Pacific islands (Polynesia, Melanesia and Micronesia). | I9: Kava (Piper methysticum) is a shrub monograph focused on the root; rhizome used in herbal preparations. It is associated with Indigenous to the South Pacific islands (Polynesia, Melanesia and Micronesia). Kavalactones modulate GABA-A receptors and ion channels, producing anxiolytic and sedative effects without classical benzodiazepine-site binding. Rare but serious liver injury has been reported, especially with nontraditional extracts or concurrent alcohol/hepatotoxic drug use. | J9: Kava is represented here as a monograph-style entry centered on the root; rhizome. Key reported compounds include kavain; dihydrokavain; methysticin; dihydromethysticin; yangonin; desmethoxyyangonin; flavokavain A/B/C. Typical preparation forms: Traditional aqueous root beverage; modern standardized root extracts. Kavalactones modulate GABA-A receptors and ion channels, producing anxiolytic and sedative effects without classical benzodiazepine-site binding. Interaction profile: Additive sedation with CNS depressants and alcohol; possible hepatic enzyme interactions. Use caution or avoid in: Liver disease, pregnancy, breastfeeding, concurrent CNS depressants or hepatotoxic drugs. | K9: kavain; dihydrokavain; methysticin; dihydromethysticin; yangonin; desmethoxyyangonin; flavokavain A/B/C | L9: total kavalactones | M9: Kavalactones modulate GABA-A receptors and ion channels, producing anxiolytic and sedative effects without classical benzodiazepine-site binding. | N9: gabaergic | O9: human + preclinical | P9: Rare but serious liver injury has been reported, especially with nontraditional extracts or concurrent alcohol/hepatotoxic drug use. | Q9: Additive sedation with CNS depressants and alcohol; possible hepatic enzyme interactions. | R9: Liver disease, pregnancy, breastfeeding, concurrent CNS depressants or hepatotoxic drugs. | S9: Traditional aqueous root beverage; modern standardized root extracts. | T9: ~250 mg/day total kavalactones upper practical limit | U9: Standardized to kavalactone content. | V9: Avoid stems/leaves; extraction method matters. | W9: medium | X9: schema-upgraded | Y9: Recovered from prior batch output in this conversation | Z9: needs-source-normalization | AA9: conversation-recovered | AB9: Recovered from prior batch output in this conversation | AC9: Recovered from prior batch output in this conversation | AD9: Recovered from prior batch output in this conversation | AE9: Recovered from prior batch output in this conversation | AF9: Separate traditional aqueous prep from solvent extracts. | AG9: 2 | AH9: 3 | AI9: 1 | AJ9: 6 | AK9: High | AL9: Present | AM9: Conversation-recovered | AN9: 1 | AO9: Near ready | AP9: Research | AR9: Source review | AS9: Not started | AT9: No | AU9: No | AV9: Yes | AW9: Normalize source record | AX9: 1 | BA9: =IF($AR9="Published","Published",IF($AS9="Passed","Approved",IF($AR9="Ready for QA","QA review",IF($AR9="Source review","Source review",IF($AR9="Editorial polish","Editorial review","Review pending"))))) | BB9: =IF(OR($AR9="Published",$AS9="Passed",AND($AY9<>"",$BD9<>"")),"Approved",IF(OR($AY9<>"",$BC9<>"",$BF9<>""),"In review","Pending")) | BE9: =IF(OR($AY9<>"",$AZ9<>"",$BC9<>"",$BF9<>""),TODAY(),"") | BG9: =$B9&"-R"&$AX9 | BH9: =COUNTIF('Change History'!$C:$C,$B9)
A10: Lemon Balm | B10: lemon-balm | C10: Melissa officinalis | D10: herb | E10: herb | F10: leaf; aerial parts | H10: Europe, Mediterranean | I10: Lemon Balm (Melissa officinalis) is a herb monograph focused on the leaf; aerial parts used in herbal preparations. It is associated with Europe, Mediterranean. GABAergic (GABA transaminase inhibition); mild cholinergic activity. Generally safe; mild sedation possible. | J10: Lemon Balm is represented here as a monograph-style entry centered on the leaf; aerial parts. Key reported compounds include rosmarinic acid; citral; citronellal; linalool; flavonoids. Typical preparation forms: Leaf extracts, teas, tinctures. GABAergic (GABA transaminase inhibition); mild cholinergic activity. Interaction profile: Sedatives, thyroid medications. Use caution or avoid in: Hypothyroidism (caution). | K10: rosmarinic acid; citral; citronellal; linalool; flavonoids | L10: rosmarinic acid | M10: GABAergic (GABA transaminase inhibition); mild cholinergic activity | N10: gabaergic; cholinergic; antioxidant | O10: preclinical + limited human | P10: Generally safe; mild sedation possible | Q10: Sedatives, thyroid medications | R10: Hypothyroidism (caution) | S10: Leaf extracts, teas, tinctures | U10: Rosmarinic acid content | W10: medium | X10: schema-upgraded | Y10: EMA herbal monograph; NCCIH | Z10: present | AA10: NCCIH; EMA | AB10: EMA herbal monograph; NCCIH | AC10: EMA herbal monograph; NCCIH | AD10: EMA herbal monograph; NCCIH | AE10: EMA herbal monograph; NCCIH | AF10: Carried forward from batch CSV; needs source-linked monograph expansion. | AG10: 2 | AH10: 3 | AI10: 3 | AJ10: 8 | AK10: Medium | AL10: Missing | AM10: Linked primary/secondary | AN10: 0.92857143 | AO10: Ready | AP10: Editorial | AR10: Ready for QA | AS10: Not started | AT10: Yes | AU10: Yes | AV10: Yes | AX10: 1 | BA10: =IF($AR10="Published","Published",IF($AS10="Passed","Approved",IF($AR10="Ready for QA","QA review",IF($AR10="Source review","Source review",IF($AR10="Editorial polish","Editorial review","Review pending"))))) | BB10: =IF(OR($AR10="Published",$AS10="Passed",AND($AY10<>"",$BD10<>"")),"Approved",IF(OR($AY10<>"",$BC10<>"",$BF10<>""),"In review","Pending")) | BE10: =IF(OR($AY10<>"",$AZ10<>"",$BC10<>"",$BF10<>""),TODAY(),"") | BG10: =$B10&"-R"&$AX10 | BH10: =COUNTIF('Change History'!$C:$C,$B10)
A11: Maca | B11: maca | C11: Lepidium meyenii | D11: herb | E11: root | F11: root; hypocotyl | H11: Peru (Andes) | I11: Maca (Lepidium meyenii) is a root monograph focused on the root; hypocotyl used in herbal preparations. It is associated with Peru (Andes). May influence endocrine signaling and energy metabolism (unclear mechanism). Generally safe; mild GI upset possible. | J11: Maca is represented here as a monograph-style entry centered on the root; hypocotyl. Key reported compounds include macamides; macaenes; glucosinolates. Typical preparation forms: Dried root powder, extracts. May influence endocrine signaling and energy metabolism (unclear mechanism). Interaction profile: Limited data. Use caution or avoid in: Hormone-sensitive conditions (caution). | K11: macamides; macaenes; glucosinolates | L11: macamides | M11: May influence endocrine signaling and energy metabolism (unclear mechanism) | N11: adaptogen; hormonal | O11: preclinical + limited human | P11: Generally safe; mild GI upset possible | Q11: Limited data | R11: Hormone-sensitive conditions (caution) | S11: Dried root powder, extracts | W11: medium | X11: schema-upgraded | Y11: PubMed; NIH | Z11: present | AA11: NIH/ODS; PubMed/PMC | AB11: PubMed; NIH | AC11: PubMed; NIH | AD11: PubMed; NIH | AE11: PubMed; NIH | AF11: Carried forward from batch CSV; needs source-linked monograph expansion. | AG11: 2 | AH11: 3 | AI11: 3 | AJ11: 8 | AK11: Medium | AL11: Missing | AM11: Linked primary/secondary | AN11: 0.85714286 | AO11: Ready | AP11: Editorial | AR11: Ready for QA | AS11: Not started | AT11: Yes | AU11: Yes | AV11: Yes | AX11: 1 | BA11: =IF($AR11="Published","Published",IF($AS11="Passed","Approved",IF($AR11="Ready for QA","QA review",IF($AR11="Source review","Source review",IF($AR11="Editorial polish","Editorial review","Review pending"))))) | BB11: =IF(OR($AR11="Published",$AS11="Passed",AND($AY11<>"",$BD11<>"")),"Approved",IF(OR($AY11<>"",$BC11<>"",$BF11<>""),"In review","Pending")) | BE11: =IF(OR($AY11<>"",$AZ11<>"",$BC11<>"",$BF11<>""),TODAY(),"") | BG11: =$B11&"-R"&$AX11 | BH11: =COUNTIF('Change History'!$C:$C,$B11)
A12: Milk Thistle | B12: milk-thistle | C12: Silybum marianum | D12: herb | E12: herb | F12: seed; fruit | G12: milk thistle; St. Mary's thistle; blessed milkthistle | H12: Native to the Mediterranean region; now naturalized worldwide. | I12: Milk Thistle (Silybum marianum) is a herb monograph focused on the seed; fruit used in herbal preparations. It is associated with Native to the Mediterranean region; now naturalized worldwide. Silymarin flavonolignans exhibit antioxidant, anti-inflammatory and antifibrotic activity relevant to hepatoprotection. Generally well tolerated; mild GI side effects and occasional allergic reactions. | J12: Milk Thistle is represented here as a monograph-style entry centered on the seed; fruit. Key reported compounds include silybin A/B; isosilybin A/B; silychristin; silydianin; isosilychristin. Typical preparation forms: Seed/fruit extracts standardized to silymarin. Silymarin flavonolignans exhibit antioxidant, anti-inflammatory and antifibrotic activity relevant to hepatoprotection. Interaction profile: Possible CYP2C9/CYP3A4 interaction risk; may affect warfarin and some other drugs. Use caution or avoid in: Asteraceae allergy; caution in pregnancy/breastfeeding. | K12: silybin A/B; isosilybin A/B; silychristin; silydianin; isosilychristin | L12: silymarin; silybin | M12: Silymarin flavonolignans exhibit antioxidant, anti-inflammatory and antifibrotic activity relevant to hepatoprotection. | N12: antioxidant; anti-inflammatory; hepatoprotective | O12: human + preclinical | P12: Generally well tolerated; mild GI side effects and occasional allergic reactions. | Q12: Possible CYP2C9/CYP3A4 interaction risk; may affect warfarin and some other drugs. | R12: Asteraceae allergy; caution in pregnancy/breastfeeding. | S12: Seed/fruit extracts standardized to silymarin. | T12: 250–750 mg silymarin 2–3 times daily | U12: Typically 70–80% silymarin. | W12: high | X12: schema-upgraded | Y12: Recovered from prior batch output in this conversation | Z12: needs-source-normalization | AA12: conversation-recovered | AB12: Recovered from prior batch output in this conversation | AC12: Recovered from prior batch output in this conversation | AD12: Recovered from prior batch output in this conversation | AE12: Recovered from prior batch output in this conversation | AF12: Keep hepatoprotective claims narrower than “treats liver disease.” | AG12: 3 | AH12: 3 | AI12: 1 | AJ12: 7 | AK12: High | AL12: Present | AM12: Conversation-recovered | AN12: 1 | AO12: Near ready | AP12: Research | AR12: Source review | AS12: Not started | AT12: No | AU12: No | AV12: Yes | AW12: Normalize source record | AX12: 1 | BA12: =IF($AR12="Published","Published",IF($AS12="Passed","Approved",IF($AR12="Ready for QA","QA review",IF($AR12="Source review","Source review",IF($AR12="Editorial polish","Editorial review","Review pending"))))) | BB12: =IF(OR($AR12="Published",$AS12="Passed",AND($AY12<>"",$BD12<>"")),"Approved",IF(OR($AY12<>"",$BC12<>"",$BF12<>""),"In review","Pending")) | BE12: =IF(OR($AY12<>"",$AZ12<>"",$BC12<>"",$BF12<>""),TODAY(),"") | BG12: =$B12&"-R"&$AX12 | BH12: =COUNTIF('Change History'!$C:$C,$B12)
A13: Peppermint | B13: peppermint | C13: Mentha × piperita | D13: herb | E13: herb | F13: unspecified | G13: peppermint; Mentha × piperita | H13: Peppermint is a hybrid between water mint and spearmint that grows throughout Europe, North America and the Mediterranean【376436993997216†L159-L162】. | I13: Peppermint (Mentha × piperita) is a herb monograph focused on the unspecified used in herbal preparations. It is associated with Peppermint is a hybrid between water mint and spearmint that grows throughout Europe, North America and the Mediterranean【376436993997216†L159-L162】. Peppermint oil contains more than 80 constituents; menthol is the main bioactive component. Menthol is generally regarded as safe. | J13: Peppermint is represented here as a monograph-style entry centered on the unspecified. Key reported compounds include l‑menthol; l‑menthone; isomenthone; menthyl acetate; 1,8‑cineole (eucalyptol); menthofuran; limonene. Typical preparation forms: Leaves and flowering tops are used fresh or dried to make teas and flavourings. Medicinal products include enteric‑coated capsules of peppermint oil and topical preparations. Peppermint oil contains more than 80 constituents; menthol is the main bioactive component. Menthol acts as a smooth‑muscle relaxant by blocking L‑type calcium channels and activating transient receptor potential channels (TRPM8 and TRPA1). These actions underlie the spasmolytic and analgesic properties of peppermint oil. Peppermint oil also has antimicrobial, antiviral and anti‑inflammatory effects【271856535371736†L224-L289】【271856535371736†L312-L333】. Interaction profile: Peppermint oil may inhibit cytochrome P450 enzymes (e.g., CYP2A6 and UGT2B7) and could theoretically interact with drugs metabolised by these pathways. Use caution or avoid in: Avoid in infants and young children, and in people with gastro‑oesophageal reflux disease or bile duct obstruction. Use cautiously in those taking hepatotoxic drugs due to potential pulegone/menthofuran toxicity. | K13: l‑menthol; l‑menthone; isomenthone; menthyl acetate; 1,8‑cineole (eucalyptol); menthofuran; limonene | M13: Peppermint oil contains more than 80 constituents; menthol is the main bioactive component. Menthol acts as a smooth‑muscle relaxant by blocking L‑type calcium channels and activating transient receptor potential channels (TRPM8 and TRPA1). These actions underlie the spasmolytic and analgesic properties of peppermint oil. Peppermint oil also has antimicrobial, antiviral and anti‑inflammatory effects【271856535371736†L224-L289】【271856535371736†L312-L333】. | N13: anti-inflammatory; spasmolytic; antimicrobial | P13: Menthol is generally regarded as safe. Enteric‑coated peppermint oil is well tolerated; the most common adverse effects reported in clinical trials are heartburn, nausea, abdominal pain and dry mouth【220193048567304†L45-L53】. High doses of minor constituents such as pulegone or menthofuran can cause hepatotoxicity in animals, but typical medicinal doses contain negligible amounts and no cases of human hepatotoxicity have been reported【271856535371736†L1296-L1354】. Peppermint oil should not be applied near the faces of infants or young children because menthol inhalation can cause serious adverse reactions【220193048567304†L45-L53】. | Q13: Peppermint oil may inhibit cytochrome P450 enzymes (e.g., CYP2A6 and UGT2B7) and could theoretically interact with drugs metabolised by these pathways. | R13: Avoid in infants and young children, and in people with gastro‑oesophageal reflux disease or bile duct obstruction. Use cautiously in those taking hepatotoxic drugs due to potential pulegone/menthofuran toxicity. | S13: Leaves and flowering tops are used fresh or dried to make teas and flavourings. Medicinal products include enteric‑coated capsules of peppermint oil and topical preparations. | W13: medium | X13: schema-upgraded | Y13: 【697136726945063†L340-L345】; 【271856535371736†L224-L289】; 【271856535371736†L312-L333】; 【220193048567304†L45-L53】; 【271856535371736†L1296-L1354】; 【376436993997216†L159-L162】 | Z13: present | AA13: PubMed/PMC | AB13: 【697136726945063†L340-L345】; 【271856535371736†L224-L289】; 【271856535371736†L312-L333】; 【220193048567304†L45-L53】; 【271856535371736†L1296-L1354】; 【376436993997216†L159-L162】 | AC13: 【697136726945063†L340-L345】; 【271856535371736†L224-L289】; 【271856535371736†L312-L333】; 【220193048567304†L45-L53】; 【271856535371736†L1296-L1354】; 【376436993997216†L159-L162】 | AD13: 【697136726945063†L340-L345】; 【271856535371736†L224-L289】; 【271856535371736†L312-L333】; 【220193048567304†L45-L53】; 【271856535371736†L1296-L1354】; 【376436993997216†L159-L162】 | AE13: 【697136726945063†L340-L345】; 【271856535371736†L224-L289】; 【271856535371736†L312-L333】; 【220193048567304†L45-L53】; 【271856535371736†L1296-L1354】; 【376436993997216†L159-L162】 | AF13: Mechanism preserved as qualified language where evidence is preclinical. | AG13: 2 | AH13: 1 | AI13: 3 | AJ13: 6 | AK13: Medium | AL13: Missing | AM13: Linked primary/secondary | AN13: 0.71428571 | AO13: Near ready | AP13: Editorial | AR13: Editorial polish | AS13: Not started | AT13: Yes | AU13: No | AV13: Yes | AW13: Finalize remaining content gaps | AX13: 1 | BA13: =IF($AR13="Published","Published",IF($AS13="Passed","Approved",IF($AR13="Ready for QA","QA review",IF($AR13="Source review","Source review",IF($AR13="Editorial polish","Editorial review","Review pending"))))) | BB13: =IF(OR($AR13="Published",$AS13="Passed",AND($AY13<>"",$BD13<>"")),"Approved",IF(OR($AY13<>"",$BC13<>"",$BF13<>""),"In review","Pending")) | BE13: =IF(OR($AY13<>"",$AZ13<>"",$BC13<>"",$BF13<>""),TODAY(),"") | BG13: =$B13&"-R"&$AX13 | BH13: =COUNTIF('Change History'!$C:$C,$B13)
A14: Rhodiola Rosea | B14: rhodiola-rosea | C14: Rhodiola rosea | D14: herb | E14: adaptogenic root | F14: root | H14: Europe, Asia (cold regions) | I14: Rhodiola Rosea (Rhodiola rosea) is a adaptogenic root monograph focused on the root used in herbal preparations. It is associated with Europe, Asia (cold regions). Adaptogen; modulates HPA axis; influences serotonin, dopamine, norepinephrine; antioxidant. Generally well tolerated; possible dizziness, dry mouth, insomnia. | J14: Rhodiola Rosea is represented here as a monograph-style entry centered on the root. Key reported compounds include rosavin; rosarin; rosin; salidroside; tyrosol. Typical preparation forms: Standardized root extracts. Adaptogen; modulates HPA axis; influences serotonin, dopamine, norepinephrine; antioxidant. Interaction profile: SSRIs, MAOIs, stimulants. Use caution or avoid in: Bipolar disorder; avoid high doses before sleep. | K14: rosavin; rosarin; rosin; salidroside; tyrosol | L14: rosavins; salidroside | M14: Adaptogen; modulates HPA axis; influences serotonin, dopamine, norepinephrine; antioxidant | N14: adaptogen; serotonergic; dopaminergic; antioxidant | O14: preclinical + limited human | P14: Generally well tolerated; possible dizziness, dry mouth, insomnia | Q14: SSRIs, MAOIs, stimulants | R14: Bipolar disorder; avoid high doses before sleep | S14: Standardized root extracts | U14: Typically 3% rosavins, 1% salidroside | W14: medium | X14: schema-upgraded | Y14: NCCIH; PubMed adaptogen reviews | Z14: present | AA14: NCCIH; PubMed/PMC | AB14: NCCIH; PubMed adaptogen reviews | AC14: NCCIH; PubMed adaptogen reviews | AD14: NCCIH; PubMed adaptogen reviews | AE14: NCCIH; PubMed adaptogen reviews | AF14: Carried forward from batch CSV; needs source-linked monograph expansion. | AG14: 2 | AH14: 3 | AI14: 3 | AJ14: 8 | AK14: Medium | AL14: Missing | AM14: Linked primary/secondary | AN14: 0.92857143 | AO14: Ready | AP14: Editorial | AR14: Ready for QA | AS14: Not started | AT14: Yes | AU14: Yes | AV14: Yes | AX14: 1 | BA14: =IF($AR14="Published","Published",IF($AS14="Passed","Approved",IF($AR14="Ready for QA","QA review",IF($AR14="Source review","Source review",IF($AR14="Editorial polish","Editorial review","Review pending"))))) | BB14: =IF(OR($AR14="Published",$AS14="Passed",AND($AY14<>"",$BD14<>"")),"Approved",IF(OR($AY14<>"",$BC14<>"",$BF14<>""),"In review","Pending")) | BE14: =IF(OR($AY14<>"",$AZ14<>"",$BC14<>"",$BF14<>""),TODAY(),"") | BG14: =$B14&"-R"&$AX14 | BH14: =COUNTIF('Change History'!$C:$C,$B14)
A15: Saw Palmetto | B15: saw-palmetto | C15: Serenoa repens | D15: herb | E15: berry extract | F15: berry | H15: Southeastern United States | I15: Saw Palmetto (Serenoa repens) is a berry extract monograph focused on the berry used in herbal preparations. It is associated with Southeastern United States. 5-alpha-reductase inhibition; anti-androgenic effects. Generally safe; mild GI upset, headache. | J15: Saw Palmetto is represented here as a monograph-style entry centered on the berry. Key reported compounds include fatty acids; phytosterols (beta-sitosterol). Typical preparation forms: Berry extracts. 5-alpha-reductase inhibition; anti-androgenic effects. Interaction profile: Hormonal therapies, anticoagulants. Use caution or avoid in: Pregnancy. | K15: fatty acids; phytosterols (beta-sitosterol) | L15: fatty acids; beta-sitosterol | M15: 5-alpha-reductase inhibition; anti-androgenic effects | N15: hormonal; anti-androgenic | O15: preclinical + limited human | P15: Generally safe; mild GI upset, headache | Q15: Hormonal therapies, anticoagulants | R15: Pregnancy | S15: Berry extracts | U15: Standardized to fatty acid content | W15: medium | X15: schema-upgraded | Y15: NIH ODS; EMA | Z15: present | AA15: NIH/ODS; EMA | AB15: NIH ODS; EMA | AC15: NIH ODS; EMA | AD15: NIH ODS; EMA | AE15: NIH ODS; EMA | AF15: Carried forward from batch CSV; needs source-linked monograph expansion. | AG15: 2 | AH15: 3 | AI15: 3 | AJ15: 8 | AK15: Medium | AL15: Missing | AM15: Linked primary/secondary | AN15: 0.92857143 | AO15: Ready | AP15: Editorial | AR15: Ready for QA | AS15: Not started | AT15: Yes | AU15: Yes | AV15: Yes | AX15: 1 | BA15: =IF($AR15="Published","Published",IF($AS15="Passed","Approved",IF($AR15="Ready for QA","QA review",IF($AR15="Source review","Source review",IF($AR15="Editorial polish","Editorial review","Review pending"))))) | BB15: =IF(OR($AR15="Published",$AS15="Passed",AND($AY15<>"",$BD15<>"")),"Approved",IF(OR($AY15<>"",$BC15<>"",$BF15<>""),"In review","Pending")) | BE15: =IF(OR($AY15<>"",$AZ15<>"",$BC15<>"",$BF15<>""),TODAY(),"") | BG15: =$B15&"-R"&$AX15 | BH15: =COUNTIF('Change History'!$C:$C,$B15)
A16: St Johns Wort | B16: st-johns-wort | C16: Hypericum perforatum | D16: herb | E16: herb | F16: flowering tops | G16: St. John's wort; Hypericum; goatweed | H16: Native to Europe and West Asia; naturalized in North America and other temperate regions. | I16: St. John's wort (Hypericum perforatum) is a herb monograph focused on the flowering tops used in herbal preparations. It is associated with Native to Europe and West Asia; naturalized in North America and other temperate regions. Hyperforin and related compounds inhibit monoamine reuptake and affect TRPC6-linked neuroplasticity; additional monoamine oxidase and stress-pathway effects have been proposed. Can cause photosensitivity, GI upset, dizziness, insomnia, restlessness. | J16: St. John's wort is represented here as a monograph-style entry centered on the flowering tops. Key reported compounds include hyperforin; hypericin; pseudohypericin; quercetin; rutin; kaempferol. Typical preparation forms: Dried flowering tops or standardized extracts. Hyperforin and related compounds inhibit monoamine reuptake and affect TRPC6-linked neuroplasticity; additional monoamine oxidase and stress-pathway effects have been proposed. Interaction profile: Major interactions with antidepressants, oral contraceptives, cyclosporine, tacrolimus, HIV meds, anticancer drugs, warfarin, digoxin and others. Use caution or avoid in: Pregnancy, breastfeeding, bipolar disorder, concomitant prescription meds with CYP/P-gp liability. | K16: hyperforin; hypericin; pseudohypericin; quercetin; rutin; kaempferol | L16: hyperforin; hypericin | M16: Hyperforin and related compounds inhibit monoamine reuptake and affect TRPC6-linked neuroplasticity; additional monoamine oxidase and stress-pathway effects have been proposed. | N16: serotonergic; dopaminergic | O16: human + preclinical | P16: Can cause photosensitivity, GI upset, dizziness, insomnia, restlessness. Strong inducer of CYP3A4 and P-gp. | Q16: Major interactions with antidepressants, oral contraceptives, cyclosporine, tacrolimus, HIV meds, anticancer drugs, warfarin, digoxin and others. | R16: Pregnancy, breastfeeding, bipolar disorder, concomitant prescription meds with CYP/P-gp liability. | S16: Dried flowering tops or standardized extracts. | T16: 300 mg extract three times daily | U16: Often 0.3% hypericin or 2–5% hyperforin. | W16: high | X16: schema-upgraded | Y16: Recovered from prior batch output in this conversation | Z16: needs-source-normalization | AA16: conversation-recovered | AB16: Recovered from prior batch output in this conversation | AC16: Recovered from prior batch output in this conversation | AD16: Recovered from prior batch output in this conversation | AE16: Recovered from prior batch output in this conversation | AF16: Flag as high-interaction herb. | AG16: 3 | AH16: 3 | AI16: 1 | AJ16: 7 | AK16: High | AL16: Present | AM16: Conversation-recovered | AN16: 1 | AO16: Near ready | AP16: Research | AR16: Source review | AS16: Not started | AT16: No | AU16: No | AV16: Yes | AW16: Normalize source record | AX16: 1 | BA16: =IF($AR16="Published","Published",IF($AS16="Passed","Approved",IF($AR16="Ready for QA","QA review",IF($AR16="Source review","Source review",IF($AR16="Editorial polish","Editorial review","Review pending"))))) | BB16: =IF(OR($AR16="Published",$AS16="Passed",AND($AY16<>"",$BD16<>"")),"Approved",IF(OR($AY16<>"",$BC16<>"",$BF16<>""),"In review","Pending")) | BE16: =IF(OR($AY16<>"",$AZ16<>"",$BC16<>"",$BF16<>""),TODAY(),"") | BG16: =$B16&"-R"&$AX16 | BH16: =COUNTIF('Change History'!$C:$C,$B16)
